Starting server in PID 3696.
Traceback (most recent call last):
  File "/home/ec2-user/py/bin/pserve", line 9, in <module>
    load_entry_point('pyramid', 'console_scripts', 'pserve')()
  File "/home/ec2-user/py/lib/python3.5/site-packages/pyramid/scripts/pserve.py", line 60, in main
    return command.run()
  File "/home/ec2-user/py/lib/python3.5/site-packages/pyramid/scripts/pserve.py", line 403, in run
    serve()
  File "/home/ec2-user/py/lib/python3.5/site-packages/pyramid/scripts/pserve.py", line 382, in serve
    server(app)
  File "/home/ec2-user/py/lib/python3.5/site-packages/paste/deploy/loadwsgi.py", line 189, in server_wrapper
    **context.local_conf)
  File "/home/ec2-user/py/lib/python3.5/site-packages/paste/deploy/util.py", line 55, in fix_call
    val = callable(*args, **kw)
  File "/home/ec2-user/py/lib/python3.5/site-packages/waitress-1.0a2-py3.5.egg/waitress/__init__.py", line 20, in serve_paste
    serve(app, **kw)
  File "/home/ec2-user/py/lib/python3.5/site-packages/waitress-1.0a2-py3.5.egg/waitress/__init__.py", line 11, in serve
    server = _server(app, **kw)
  File "/home/ec2-user/py/lib/python3.5/site-packages/waitress-1.0a2-py3.5.egg/waitress/server.py", line 78, in create_server
    sockinfo=sockinfo)
  File "/home/ec2-user/py/lib/python3.5/site-packages/waitress-1.0a2-py3.5.egg/waitress/server.py", line 175, in __init__
    self.bind_server_socket()
  File "/home/ec2-user/py/lib/python3.5/site-packages/waitress-1.0a2-py3.5.egg/waitress/server.py", line 287, in bind_server_socket
    self.bind(sockaddr)
  File "/usr/local/lib/python3.5/asyncore.py", line 329, in bind
    return self.socket.bind(addr)
OSError: [Errno 98] Address already in use
Starting subprocess with file monitor
Traceback (most recent call last):
  File "/home/ec2-user/py/bin/pserve", line 9, in <module>
    load_entry_point('pyramid', 'console_scripts', 'pserve')()
  File "/home/ec2-user/py/lib/python3.5/site-packages/pyramid/scripts/pserve.py", line 60, in main
    return command.run()
  File "/home/ec2-user/py/lib/python3.5/site-packages/pyramid/scripts/pserve.py", line 371, in run
    global_conf=vars)
  File "/home/ec2-user/py/lib/python3.5/site-packages/pyramid/scripts/pserve.py", line 406, in loadapp
    return loadapp(app_spec, name=name, relative_to=relative_to, **kw)
  File "/home/ec2-user/py/lib/python3.5/site-packages/paste/deploy/loadwsgi.py", line 247, in loadapp
    return loadobj(APP, uri, name=name, **kw)
  File "/home/ec2-user/py/lib/python3.5/site-packages/paste/deploy/loadwsgi.py", line 271, in loadobj
    global_conf=global_conf)
  File "/home/ec2-user/py/lib/python3.5/site-packages/paste/deploy/loadwsgi.py", line 296, in loadcontext
    global_conf=global_conf)
  File "/home/ec2-user/py/lib/python3.5/site-packages/paste/deploy/loadwsgi.py", line 320, in _loadconfig
    return loader.get_context(object_type, name, global_conf)
  File "/home/ec2-user/py/lib/python3.5/site-packages/paste/deploy/loadwsgi.py", line 454, in get_context
    section)
  File "/home/ec2-user/py/lib/python3.5/site-packages/paste/deploy/loadwsgi.py", line 476, in _context_from_use
    object_type, name=use, global_conf=global_conf)
  File "/home/ec2-user/py/lib/python3.5/site-packages/paste/deploy/loadwsgi.py", line 406, in get_context
    global_conf=global_conf)
  File "/home/ec2-user/py/lib/python3.5/site-packages/paste/deploy/loadwsgi.py", line 296, in loadcontext
    global_conf=global_conf)
  File "/home/ec2-user/py/lib/python3.5/site-packages/paste/deploy/loadwsgi.py", line 328, in _loadegg
    return loader.get_context(object_type, name, global_conf)
  File "/home/ec2-user/py/lib/python3.5/site-packages/paste/deploy/loadwsgi.py", line 620, in get_context
    object_type, name=name)
  File "/home/ec2-user/py/lib/python3.5/site-packages/paste/deploy/loadwsgi.py", line 640, in find_egg_entry_point
    pkg_resources.require(self.spec)
  File "/home/ec2-user/py/lib/python3.5/site-packages/pkg_resources/__init__.py", line 943, in require
    needed = self.resolve(parse_requirements(requirements))
  File "/home/ec2-user/py/lib/python3.5/site-packages/pkg_resources/__init__.py", line 829, in resolve
    raise DistributionNotFound(req, requirers)
pkg_resources.DistributionNotFound: The 'floof' distribution was not found and is required by the application
Starting subprocess with file monitor
-------------------- Restarting --------------------
-------------------- Restarting --------------------
-------------------- Restarting --------------------
-------------------- Restarting --------------------
